2017-06-28 16:19:07,727 - mylogger - ERROR - There was an exception in  calculate
Traceback (most recent call last):
  File "C:\Users\qfWu\Desktop\intelligentCampus\ÖÇ»ÛÐ£Ô°\Tools\MyLog.py", line 27, in wrapper
    return function(*args, **kwargs)
  File "C:\Users\qfWu\Desktop\intelligentCampus\ÖÇ»ÛÐ£Ô°\a_CalculateField\CalculateLibraryTimes.py", line 16, in calculate
    1 / 0
ZeroDivisionError: division by zero
2017-06-28 16:19:40,689 - mylogger - ERROR - There was an exception in  calculate
Traceback (most recent call last):
  File "C:\Users\qfWu\Desktop\intelligentCampus\ÖÇ»ÛÐ£Ô°\Tools\MyLog.py", line 27, in wrapper
    return function(*args, **kwargs)
  File "C:\Users\qfWu\Desktop\intelligentCampus\ÖÇ»ÛÐ£Ô°\a_CalculateField\CalculateLibraryTimes.py", line 16, in calculate
    1 / 0
ZeroDivisionError: division by zero
There was an exception in  calculate
There was an exception in  calculate
There was an exception in  calculate
There was an exception in  calculate
